<?xml version="1.o" ?>
<robot xmlns:xacro="http://www.ros.org/wiki/xacro" name="robot">
	<material name="grey">
		<color rgba="0.2 0.2 0.2 1"/>
	</material>
	
	<material name="white">
		<color rgba="1 1 1 1"/>
	</material>

	<material name="orange">
		<color rgba="1 0.3 0.1 1"/>
	</material>

	<material name="blue">
		<color rgba="0 0 1 1"/>
	</material>

	<link name="world"></link>

	<joint name="world_to_base" type="fixed">
		<parent link="world"/>
		<child link="base"/>
		<origin rpy="1.57 0 0" xyz="0 0 0"/>
	</joint>

	<link name="base">
		<visual>
			<origin xyz="2 0 0" rpy="0 0 0"/>
			<geometry>
				<box size="5 0.1 3"/>
			</geometry>
			<material name="grey"/>
		</visual>
	</link>

	<joint name="base_to_13" type="revolute">
		<parent link="base"/>
		<child link="13"/>
		<origin rpy="0 0 0" xyz="0 0.25 0"/>
		<axis rpy="0 0 0" xyz="0 0 1"/>
		<limit effort="0.1" lower="-3.1" upper="3.1" velocity="0.2"/>
	</joint>

	 <link name="13">
		<visual>
			<origin xyz="0.75 0 0" rpy="0 1.57 0"/>
			<geometry>
				<cylinder length="1.5" radius="0.04"/>
			</geometry>
			<material name="orange"/>
		</visual>
	</link>

	<joint name="13_to_12" type="revolute">
		<parent link="13"/>
		<child link="12"/>
		<origin rpy="0 0 0" xyz="1.5 0 0"/>
		<axis rpy="0 0 0" xyz="0 0 1"/>
		<limit effort="0.1" lower="-3.1" upper="3.1" velocity="0.2"/>
	</joint>	
			
	<link name="12">
		<visual>
			<origin xyz="0.75 0 0" rpy="0 1.57 0"/>
			<geometry>
				<cylinder length="1.5" radius="0.04"/>
			</geometry>
			<material name="orange"/>
		</visual>
	</link>

	<joint name="12_to_11" type="revolute">
		<parent link="12"/>
		<child link="11"/>
		<origin rpy="0 0 0" xyz="1.5 0 0"/>
		<axis rpy="0 0 0" xyz="0 0 1"/>
		<limit effort="0.1" lower="-3.1" upper="3.1" velocity="0.2"/>
	</joint>

	<link name="11">
		<visual>
			<origin xyz="0.5 0 0" rpy="0 1.57 0"/>
			<geometry>
				<cylinder length="1" radius="0.04"/>
			</geometry>
			<material name="orange"/>
		</visual>
	</link>

	<joint name="11_to_grip" type="revolute">
		<parent link="11"/>
		<child link="grip"/>
		<origin rpy="0 0 0" xyz="1 0 0"/>
		<axis rpy="0 0 0" xyz="0 0 1"/>
		<limit effort="0.1" lower="-3.1" upper="3.1" velocity="0.2"/>
	</joint>

	<link name="grip">
		<visual>
			<origin xyz="0.25 0 0"/>
			<geometry>
				<box size="0.5 0.5 0.05"/>
			</geometry>
			<material name="white"/>
		</visual>
	</link>

	<joint name="world_to_camera" type="fixed">
		<parent link="world"/>
		<child link="camera"/>
		<origin rpy="-2 0 2.5" xyz="4 1 2"/>
	</joint>

	<link name="camera">
		<visual>
			<origin xyz="0 0 -0.2"/>
			<geometry>
				<box size="0.2 0.2 0.4"/>
			</geometry>
			<material name="blue"/>
		</visual>
	</link>
</robot>
	

			  
